Workbook

Sheet Léeme
A1: CALCULADORA DE COSTOS — ARIA (Connectview) · v3 2026-06-07
A3: Cómo usarla:
A4: 1. Editá la hoja 'Parametros' (volúmenes por escenario: agentes, llamadas, mensajes, etc.).
A5: 2. Si cambian los precios, editá 'Precios' (precios unitarios y supuestos).
A6: 3. 'CostoCliente', 'CostoARIA', 'Resumen' y 'PrecioARIA' recalculan automáticamente.
A8: Dos perspectivas (modelo BYO):
A9: • Costo del CLIENTE = lo que la empresa paga a AWS en SU propia cuenta
A10: (Amazon Connect, telefonía, WhatsApp, Bedrock, DynamoDB de negocio, S3 de grabaciones).
A11: La licencia de Salesforce es EXTERNA (no AWS) y se muestra aparte, fuera del TOTAL AWS.
A12: • Costo de ARIA = lo que paga la plataforma por operar el servicio para ese tenant
A13: (Lambda, DynamoDB de metadata, Cognito, Secrets Manager, CloudWatch, hosting, transferencia).
A15: Escenarios de referencia: Piloto (~5 agentes), Pyme (~25), Enterprise (~100). Todo es editable.
... A37: Generada con: node scripts/gen-costos-xlsx.mjs

Sheet UDEP (real)
A1: UDEP — caso real: factura AWS hoy vs. con ARIA
A2: Factura real de Amazon Connect (1 mes, us-east-1). Total $426.93. Escala ~4 agentes (3 autores + 1 lector QuickSight; 8.956 min de voz ≈ 149 h/mes). Telefonía $0 en AWS → BYOC/SIP propia. Cada precio unitario coincide exacto con la hoja 'Precios'.
A4: Servicio AWS (factura real) | B4: USD/mes | C4: % factura | D4: ¿ARIA lo reemplaza? | E4: Detalle
A5: Amazon Connect — voz (end-customer-mins) | B5: 161.2 | C5: =B5/$B$22 | D5: No (core) | E5: 8.955,65 min × $0.018/min
A6: QuickSight (3 autores + 1 lector) | B6: 75 | C6: =B6/$B$22 | D6: Sí — analítica | E6: licencias por asiento ($24 + $3)
A7: Contact Lens (voz 3.432 min + chat 260 msg) | B7: 51.88 | C7: =B7/$B$22 | D7: No (core) | E7: $0.015/min voz · $0.0015/msg chat
A8: DynamoDB (306,9M lecturas / 298k escrituras) | B8: 39.2 | C8: =B8/$B$22 | D8: No (core) | E8: lectura-dominante (0,1% escritura)
A9: Kinesis (1 stream on-demand 24/7) | B9: 29.76 | C9: =B9/$B$22 | D9: Sí — analítica | E9: 744 h × $0.04
A10: OpenSearch (1× t2.small.search 24/7) | B10: 28.13 | C10: =B10/$B$22 | D10: Sí — analítica | E10: 744 h × $0.036 + 10 GB
A11: S3 — grabaciones (~1 TB) | B11: 23.82 | C11: =B11/$B$22 | D11: No (core) | E11: storage + PUT/GET
A12: Lambda | B12: 8.68 | C12: =B12/$B$22 | D12: No (core) | E12: 515k GB-s · 422k invocaciones
A13: Amazon Connect — chat | B13: 3.08 | C13: =B13/$B$22 | D13: No (core) | E13: 770 msgs × $0.004
A14: Athena | B14: 1.67 | C14: =B14/$B$22 | D14: Sí — analítica | E14: 0,333 TB × $5/TB
A15: Key Management Service (KMS) | B15: 1.57 | C15: =B15/$B$22 | D15: No (core) | E15: 1 key + 191k requests
A16: CloudWatch | B16: 1.16 | C16: =B16/$B$22 | D16: No (core) | E16: 8 alarmas + ~0,5 GB logs
... A21: Otros (Customer Profiles, Amplify, SNS, Backup, Glue) | B21: 0 | C21: =B21/$B$22 | D21: — | E21: free tier / sin cargo
A22: TOTAL factura AWS de la UDEP (USD/mes) | B22: =SUM(B5:B21)
A23: Subtotal — analítica que ARIA reemplaza (QuickSight+Kinesis+OpenSearch+Athena) | B23: =B6+B9+B10+B14
A24: Subtotal — core contact center (se mantiene en AWS) | B24: =B22-B23
A26: Comparativa: hoy (analítica DIY en AWS) vs. con ARIA
A27: Agentes UDEP (editable) | B27: 4 | E27: estimado: asientos QuickSight + volumen de voz
A28: Tarifa ARIA / agente (USD/mes, editable) | B28: 45 | E28: tarifa piloto; ver hoja 'Resumen'
A30: Concepto | B30: Hoy (DIY) | C30: Con ARIA | E30: Nota
A31: AWS — core contact center (voz, chat, CL, datos, grabaciones) | B31: =B24 | C31: =B24 | E31: igual; lo paga directo a AWS (BYO)
A32: AWS — stack de analítica (QuickSight+Kinesis+OpenSearch+Athena) | B32: =B23 | C32: =0 | E32: el dashboard de ARIA lo reemplaza
A33: Suscripción ARIA (software) | B33: =0 | C33: =B27*B28 | E33: dashboard + omnicanal + IA + soporte
A34: TOTAL mensual | B34: =B31+B32+B33 | C34: =C31+C32+C33
A35: Ahorro en infraestructura AWS (hoy → con ARIA) | C35: =B32-C32 | E35: lo que ARIA saca de la factura AWS
A36: · como % de la factura AWS de hoy | C36: =(B32-C32)/B22
A38: ▸ La infraestructura de analítica baja $134.56/mes (−31,5% de la factura AWS). La suscripción ARIA reemplaza ese pipeline (Kinesis→OpenSearch→QuickSight) —que además hay que mantener— y agrega omnicanal, IA y soporte. El software ARIA se compara contra la LICENCIA que reemplaza, no contra el total de AWS.
A40: Datos para gráficos (calculados — no editar)
A41: Voz | B41: =B5
A42: Analítica (ARIA reemplaza) | B42: =B23
A43: Contact Lens | B43: =B7
A44: DynamoDB | B44: =B8
A45: S3 grabaciones | B45: =B11
A46: Lambda | B46: =B12
A47: Otros | B47: =B22-(B5+B23+B7+B8+B11+B12)
A48: (stack) | B48: Hoy | C48: Con ARIA
A49: AWS core | B49: =B31 | C49: =C31
...

Sheet Parametros
A1: Parámetros de uso (editables) — un volumen por escenario
A3: Parámetro | B3: Piloto | C3: Pyme | D3: Enterprise | E3: Unidad / nota
A4: Agentes (en operación) | B4: 5 | C4: 25 | D4: 100 | E4: agentes
A5: Días operativos al mes | B5: 22 | C5: 22 | D5: 22 | E5: días
A6: Llamadas de voz ENTRANTES / mes | B6: 1500 | C6: 6000 | D6: 32000 | E6: llamadas
A7: Llamadas de voz SALIENTES (campañas) / mes | B7: 800 | C7: 3500 | D7: 18000 | E7: llamadas
A8: Números telefónicos (DID) activos | B8: 2 | C8: 5 | D8: 20 | E8: números
A9: Mensajes WhatsApp / mes (entrada + salida) | B9: 8000 | C9: 30000 | D9: 150000 | E9: mensajes
A10: Plantillas WhatsApp marketing (HSM) / mes | B10: 1500 | C10: 6000 | D10: 30000 | E10: mensajes Meta
A11: Chats web / mes | B11: 1000 | C11: 5000 | D11: 25000 | E11: mensajes
A12: Emails gestionados / mes | B12: 500 | C12: 2500 | D12: 12000 | E12: mensajes
A13: Conversaciones de bot/Agente IA / mes | B13: 1000 | C13: 4500 | D13: 22000 | E13: conversaciones
A14: Resúmenes IA (Bedrock) / mes | B14: 1500 | C14: 8000 | D14: 45000 | E14: invocaciones
A15: Tareas de Connect (Tasks) / mes | B15: 200 | C15: 1000 | D15: 5000 | E15: tareas
... A25: Hosting Amplify (fijo mensual) | B25: 15 | C25: 40 | D25: 120 | E25: USD/mes
A27: ▸ Editá las columnas Piloto/Pyme/Enterprise. Las hojas de costo recalculan solas.

Sheet Precios
A1: Precios unitarios y supuestos (editables) — us-east-1, jun-2026
A3: Concepto | B3: Valor | C3: Unidad | D3: Fuente / nota
A4: Amazon Connect — omnicanal (PRECIOS REALES API, efectivo 2026-05-01)
A5: Connect — chat | B5: 0.004 | C5: $/mensaje | D5: AWS Price List API (verificado)
A6: Connect — email | B6: 0.05 | C6: $/mensaje | D6: AWS Price List API (verificado)
A7: Connect — WhatsApp (WBM serviced) | B7: 0.01 | C7: $/mensaje | D7: AWS Price List API (verificado)
A8: Connect — campañas voz (conector) | B8: 0.005 | C8: $/llamada | D8: AWS Price List API (verificado)
A9: Connect — tarea (Task) | B9: 0.04 | C9: $/tarea | D9: AWS Connect pricing (Tasks)
A10: Amazon Connect — voz / telefonía (PERÚ — verificar operador/destino)
A11: Connect — uso de voz (servicio) | B11: 0.018 | C11: $/min | D11: AWS Price List API (verificado, end-customer mins)
A12: Telefonía entrante DID (Perú) | B12: 0.0075 | C12: $/min | D12: Connect Global Telephony Perú — verificar
A13: Telefonía saliente (Perú, DID) | B13: 0.0067 | C13: $/min | D13: Connect bajó Sudamérica nov-2023; móvil mayor — verificar
A14: Número DID | B14: 0.06 | C14: $/día | D14: AWS Connect pricing (rango por país)
A15: Detección de contestador (AMD) | B15: 0.0085 | C15: $/llamada | D15: AWS Connect AMD — por llamada saliente
A16: Analítica e IA de Connect — Contact Lens · Customer Profiles · Amazon Q
A17: Contact Lens — analítica de voz | B17: 0.015 | C17: $/min | D17: AWS Price List API (verificado)
A18: Contact Lens — analítica de chat | B18: 0.0015 | C18: $/mensaje | D18: AWS Price List API (verificado, ChatAnalytics)
A19: Customer Profiles — perfil utilizado/día | B19: 0.005 | C19: $/perfil-día | D19: AWS Customer Profiles (2 perfiles gratis/contacto voz·chat)
A20: Amazon Q in Connect — asistencia voz | B20: 0.008 | C20: $/min | D20: AWS Q in Connect (voz $0.008/min; chat/email/task aparte)
A21: WhatsApp — transporte AWS (EUM Social) + cargo de Meta
A22: AWS End User Messaging Social — WhatsApp | B22: 0.005 | C22: $/mensaje | D22: Transporte AWS; puede solaparse con WBM si TODO va por Connect — ajustar
A23: Meta — conversación marketing (Perú aprox.) | B23: 0.02 | C23: $/mensaje | D23: Meta cobra por mensaje desde 2025; LatAm mkt $0.02–0.07 — verificar Perú
A24: Amazon Bedrock — Claude (lista pública on-demand)
A25: Claude 3.5 Haiku — entrada | B25: 0.0008 | C25: $/1K tokens | D25: AWS Bedrock pricing (verificado, $0.80/M)
A26: Claude 3.5 Haiku — salida | B26: 0.004 | C26: $/1K tokens | D26: AWS Bedrock pricing (verificado, $4.00/M)
A27: Claude Sonnet 4 — entrada | B27: 0.003 | C27: $/1K tokens | D27: AWS Bedrock pricing
A28: Claude Sonnet 4 — salida | B28: 0.015 | C28: $/1K tokens | D28: AWS Bedrock pricing
A29: Cómputo y almacenamiento (lista pública)
A30: Lambda — solicitudes | B30: 0.2 | C30: $/1M req | D30: AWS Lambda pricing (verificado)
A31: Lambda — cómputo | B31: 1.66667e-05 | C31: $/GB-segundo | D31: AWS Lambda pricing (verificado, tier 1)
A32: DynamoDB — escritura on-demand | B32: 0.625 | C32: $/1M WRU | D32: AWS DynamoDB (verificado, recorte 50% nov-2024)
A33: DynamoDB — lectura on-demand | B33: 0.125 | C33: $/1M RRU | D33: AWS DynamoDB (verificado, recorte 50% nov-2024)
A34: S3 Standard — almacenamiento | B34: 0.023 | C34: $/GB-mes | D34: AWS S3 pricing (verificado)
A35: S3 — solicitudes PUT | B35: 0.005 | C35: $/1K | D35: AWS S3 pricing (verificado)
A36: Cognito — usuario activo (MAU) | B36: 0.015 | C36: $/MAU | D36: AWS Cognito (Essentials; Lite $0.0055)
A37: Secrets Manager — secreto | B37: 0.4 | C37: $/secreto-mes | D37: AWS Secrets Manager (verificado)
A38: CloudWatch Logs — ingesta | B38: 0.5 | C38: $/GB | D38: AWS CloudWatch (verificado)
A39: Transferencia de datos saliente | B39: 0.09 | C39: $/GB | D39: AWS pricing (verificado, primeros 10 TB)
A40: Licencias externas (NO son AWS) — software de terceros del cliente
A41: Salesforce — licencia por usuario | B41: 100 | C41: $/usuario-mes | D41: Licencia externa de Salesforce (NO AWS) — verificar plan
...

Sheet CostoCliente
A1: Costo del CLIENTE (AWS en su cuenta BYO) — USD/mes · la licencia Salesforce va aparte
A3: Concepto | B3: Piloto | C3: Pyme | D3: Enterprise | E3: Cómo se calcula
A4: Voz entrante — servicio Connect | B4: =Parametros!B6*Precios!B43*Precios!B11 | C4: =Parametros!C6*Precios!B43*Precios!B11 | D4: =Parametros!D6*Precios!B43*Precios!B11 | E4: llamadas × min × $/min
A5: Voz entrante — telefonía (DID Perú) | B5: =Parametros!B6*Precios!B43*Precios!B12 | C5: =Parametros!C6*Precios!B43*Precios!B12 | D5: =Parametros!D6*Precios!B43*Precios!B12 | E5: llamadas × min × $/min
A6: Voz saliente — servicio Connect | B6: =Parametros!B7*Precios!B44*Precios!B11 | C6: =Parametros!C7*Precios!B44*Precios!B11 | D6: =Parametros!D7*Precios!B44*Precios!B11 | E6: llamadas × min × $/min
A7: Voz saliente — telefonía (Perú) | B7: =Parametros!B7*Precios!B44*Precios!B13 | C7: =Parametros!C7*Precios!B44*Precios!B13 | D7: =Parametros!D7*Precios!B44*Precios!B13 | E7: llamadas × min × $/min
A8: Campañas de voz — conector | B8: =Parametros!B7*Precios!B8 | C8: =Parametros!C7*Precios!B8 | D8: =Parametros!D7*Precios!B8 | E8: llamadas × $/llamada
A9: Detección de contestador (AMD) — salientes | B9: =Parametros!B7*Precios!B15 | C9: =Parametros!C7*Precios!B15 | D9: =Parametros!D7*Precios!B15 | E9: llamadas salientes × $/llamada
A10: Contact Lens — analítica de VOZ | B10: =(Parametros!B6*Precios!B43+Parametros!B7*Precios!B44)*Parametros!B17*Precios!B17 | C10: =(Parametros!C6*Precios!B43+Parametros!C7*Precios!B44)*Parametros!C17*Precios!B17 | D10: =(Parametros!D6*Precios!B43+Parametros!D7*Precios!B44)*Parametros!D17*Precios!B17 | E10: min con CL × $/min
A11: Contact Lens — analítica de CHAT | B11: =Parametros!B11*Parametros!B17*Precios!B18 | C11: =Parametros!C11*Parametros!C17*Precios!B18 | D11: =Parametros!D11*Parametros!D17*Precios!B18 | E11: chats × % CL × $/msg
A12: Customer Profiles — perfil utilizado/día | B12: =(Parametros!B6+Parametros!B7+Parametros!B11+Parametros!B12)*Precios!B19 | C12: =(Parametros!C6+Parametros!C7+Parametros!C11+Parametros!C12)*Precios!B19 | D12: =(Parametros!D6+Parametros!D7+Parametros!D11+Parametros!D12)*Precios!B19 | E12: contactos × $/perfil-día (≈ perfiles únicos)
A13: Amazon Q in Connect — copiloto (voz) | B13: =(Parametros!B6*Precios!B43+Parametros!B7*Precios!B44)*Precios!B45*Precios!B20 | C13: =(Parametros!C6*Precios!B43+Parametros!C7*Precios!B44)*Precios!B45*Precios!B20 | D13: =(Parametros!D6*Precios!B43+Parametros!D7*Precios!B44)*Precios!B45*Precios!B20 | E13: min voz × % con Q × $/min
A14: Números DID (renta) | B14: =Parametros!B8*Precios!B14*Parametros!B5 | C14: =Parametros!C8*Precios!B14*Parametros!C5 | D14: =Parametros!D8*Precios!B14*Parametros!D5 | E14: números × $/día × días
A15: WhatsApp — servicio Connect (WBM) | B15: =Parametros!B9*Precios!B7 | C15: =Parametros!C9*Precios!B7 | D15: =Parametros!D9*Precios!B7 | E15: mensajes × $/msg
A16: WhatsApp — transporte AWS (EUM Social) | B16: =Parametros!B9*Precios!B22 | C16: =Parametros!C9*Precios!B22 | D16: =Parametros!D9*Precios!B22 | E16: mensajes × $/msg (verificar solapamiento con WBM)
A17: WhatsApp — conversaciones Meta (HSM) | B17: =Parametros!B10*Precios!B23 | C17: =Parametros!C10*Precios!B23 | D17: =Parametros!D10*Precios!B23 | E17: plantillas × $/msg
A18: Chat web | B18: =Parametros!B11*Precios!B5 | C18: =Parametros!C11*Precios!B5 | D18: =Parametros!D11*Precios!B5 | E18: mensajes × $/msg
A19: Email | B19: =Parametros!B12*Precios!B6 | C19: =Parametros!C12*Precios!B6 | D19: =Parametros!D12*Precios!B6 | E19: mensajes × $/msg
A20: Connect Tasks (tareas) | B20: =Parametros!B15*Precios!B9 | C20: =Parametros!C15*Precios!B9 | D20: =Parametros!D15*Precios!B9 | E20: tareas × $/tarea
A21: Bedrock — bots / Agente IA | B21: =Parametros!B13*Precios!B46*(Precios!B47/1000*Precios!B25+Precios!B48/1000*Precios!B26) | C21: =Parametros!C13*Precios!B46*(Precios!B47/1000*Precios!B25+Precios!B48/1000*Precios!B26) | D21: =Parametros!D13*Precios!B46*(Precios!B47/1000*Precios!B25+Precios!B48/1000*Precios!B26) | E21: conv × turnos × tokens × $
A22: Bedrock — resúmenes / copiloto | B22: =Parametros!B14*(Precios!B49/1000*Precios!B25+Precios!B50/1000*Precios!B26) | C22: =Parametros!C14*(Precios!B49/1000*Precios!B25+Precios!B50/1000*Precios!B26) | D22: =Parametros!D14*(Precios!B49/1000*Precios!B25+Precios!B50/1000*Precios!B26) | E22: invocaciones × tokens × $
A23: DynamoDB — datos de negocio (BYO) | B23: =Parametros!B22*Precios!B52/1000000*Precios!B32+Parametros!B22*(1-Precios!B52)/1000000*Precios!B33 | C23: =Parametros!C22*Precios!B52/1000000*Precios!B32+Parametros!C22*(1-Precios!B52)/1000000*Precios!B33 | D23: =Parametros!D22*Precios!B52/1000000*Precios!B32+Parametros!D22*(1-Precios!B52)/1000000*Precios!B33 | E23: ops × mezcla R/W × $
A24: S3 — grabaciones (almacenamiento + PUT) | B24: =Parametros!B18*Precios!B34+(Parametros!B6+Parametros!B7)/1000*Precios!B35 | C24: =Parametros!C18*Precios!B34+(Parametros!C6+Parametros!C7)/1000*Precios!B35 | D24: =Parametros!D18*Precios!B34+(Parametros!D6+Parametros!D7)/1000*Precios!B35 | E24: GB × $/GB + PUT
A25: S3 — egreso de grabaciones (reproducción/descarga) | B25: =Parametros!B19*Precios!B39 | C25: =Parametros!C19*Precios!B39 | D25: =Parametros!D19*Precios!B39 | E25: GB reproducidos × $/GB
A26: TOTAL Cliente — AWS (USD/mes) | B26: =SUM(B4:B25) | C26: =SUM(C4:C25) | D26: =SUM(D4:D25)
A27: Costo AWS por agente (USD/mes) | B27: =B26/Parametros!B4 | C27: =C26/Parametros!C4 | D27: =D26/Parametros!D4
A29: Licencias externas (NO son AWS) — se facturan aparte
A30: Salesforce — licencia (EXTERNA, no AWS) · opcional | B30: =Parametros!B16*Precios!B41 | C30: =Parametros!C16*Precios!B41 | D30: =Parametros!D16*Precios!B41 | E30: usuarios SF × $/usuario — poné 0 si no usa SF; es licencia que el cliente ya paga
A31: Subtotal licencias externas (USD/mes) | B31: =SUM(B30:B30) | C31: =SUM(C30:C30) | D31: =SUM(D30:D30)
A32: TOTAL con licencias externas (USD/mes) | B32: =B26+B31 | C32: =C26+C31 | D32: =D26+D31

Sheet CostoARIA
A1: Costo de ARIA (plataforma · cuenta 731736972577) — USD/mes por tenant
A3: Concepto | B3: Piloto | C3: Pyme | D3: Enterprise | E3: Cómo se calcula
A4: Lambda — solicitudes | B4: =Parametros!B20/1000000*Precios!B30 | C4: =Parametros!C20/1000000*Precios!B30 | D4: =Parametros!D20/1000000*Precios!B30 | E4: invocaciones × $/1M
A5: Lambda — cómputo | B5: =Parametros!B20*Precios!B51*Precios!B31 | C5: =Parametros!C20*Precios!B51*Precios!B31 | D5: =Parametros!D20*Precios!B51*Precios!B31 | E5: invocaciones × GB-s × $
A6: DynamoDB — metadata SaaS | B6: =Parametros!B21*Precios!B52/1000000*Precios!B32+Parametros!B21*(1-Precios!B52)/1000000*Precios!B33 | C6: =Parametros!C21*Precios!B52/1000000*Precios!B32+Parametros!C21*(1-Precios!B52)/1000000*Precios!B33 | D6: =Parametros!D21*Precios!B52/1000000*Precios!B32+Parametros!D21*(1-Precios!B52)/1000000*Precios!B33 | E6: ops × mezcla R/W × $
A7: Cognito — usuarios activos (MAU) | B7: =Parametros!B4*Precios!B36 | C7: =Parametros!C4*Precios!B36 | D7: =Parametros!D4*Precios!B36 | E7: agentes × $/MAU
A8: Secrets Manager | B8: =Precios!B53*Precios!B37 | C8: =Precios!B53*Precios!B37 | D8: =Precios!B53*Precios!B37 | E8: secretos × $/mes
A9: CloudWatch Logs | B9: =Parametros!B23*Precios!B38 | C9: =Parametros!C23*Precios!B38 | D9: =Parametros!D23*Precios!B38 | E9: GB × $/GB
A10: Amplify Hosting | B10: =Parametros!B25 | C10: =Parametros!C25 | D10: =Parametros!D25 | E10: fijo mensual
A11: Transferencia de datos | B11: =Parametros!B24*Precios!B39 | C11: =Parametros!C24*Precios!B39 | D11: =Parametros!D24*Precios!B39 | E11: GB × $/GB
A12: TOTAL ARIA — AWS (USD/mes) | B12: =SUM(B4:B11) | C12: =SUM(C4:C11) | D12: =SUM(D4:D11)
A13: Costo AWS por agente (USD/mes) | B13: =B12/Parametros!B4 | C13: =C12/Parametros!C4 | D13: =D12/Parametros!D4

Sheet Resumen
A1: Resumen ejecutivo de costos — USD/mes
A3: Concepto | B3: Piloto | C3: Pyme | D3: Enterprise | E3: Nota
A4: Costo del CLIENTE — AWS BYO (sin licencias) | B4: =CostoCliente!B26 | C4: =CostoCliente!C26 | D4: =CostoCliente!D26
A5: · por agente | B5: =B4/Parametros!B4 | C5: =C4/Parametros!C4 | D5: =D4/Parametros!D4
A6: Licencia Salesforce (externa, opcional) | B6: =CostoCliente!B31 | C6: =CostoCliente!C31 | D6: =CostoCliente!D31
A7: Costo de la PLATAFORMA (ARIA) | B7: =CostoARIA!B12 | C7: =CostoARIA!C12 | D7: =CostoARIA!D12
A8: · por agente | B8: =B7/Parametros!B4 | C8: =C7/Parametros!C4 | D8: =D7/Parametros!D4
A10: Opex por agente (soporte, dev, ventas) — EDITABLE | B10: 12 | C10: 8 | D10: 6 | E10: baja con la escala
A11: Costo de servir por agente (infra + opex) | B11: =B8+B10 | C11: =C8+C10 | D11: =D8+D10
A13: Tarifa ARIA por agente (USD/mes) — EDITABLE | B13: 45 | C13: 39 | D13: 29 | E13: ver análisis en hoja 'PrecioARIA'
A14: Ingreso de ARIA (tarifa × agentes) | B14: =B13*Parametros!B4 | C14: =C13*Parametros!C4 | D14: =D13*Parametros!D4
A15: Margen BRUTO de ARIA (incl. opex) | B15: =(B13-B11)/B13 | C15: =(C13-C11)/C13 | D15: =(D13-D11)/D13 | E15: el margen 'real' del SaaS
A16: Margen de contribución (solo infra) | B16: =(B14-B7)/B14 | C16: =(C14-C7)/C14 | D16: =(D14-D7)/D14 | E16: ignora opex — NO confundir con margen bruto
A17: Utilidad bruta ARIA / tenant | B17: =(B13-B11)*Parametros!B4 | C17: =(C13-C11)*Parametros!C4 | D17: =(D13-D11)*Parametros!D4
A19: COSTO TOTAL para el cliente (AWS propio + tarifa ARIA) | B19: =B4+B14 | C19: =C4+C14 | D19: =D4+D14
A20: · por agente | B20: =B19/Parametros!B4 | C20: =C19/Parametros!C4 | D20: =D19/Parametros!D4
A22: ▸ 'Costo del cliente' = lo que paga a AWS en SU cuenta (BYO); la licencia Salesforce es externa y va aparte. 'Costo de la plataforma' = lo que paga ARIA por operar. Dos márgenes: BRUTO (incl. opex, el real) y CONTRIBUCIÓN (solo infra, más alto).

Sheet PrecioARIA
A1: ¿Cuánto cobrar por ARIA? — análisis de precio (USD/mes por agente)
A3: Concepto | B3: Piloto | C3: Pyme | D3: Enterprise | E3: Nota
A4: A) Costo de servir — lo que le cuesta a ARIA operar (por agente)
A5: Costo de plataforma / agente (viene de 'Resumen') | B5: =Resumen!B8 | C5: =Resumen!C8 | D5: =Resumen!D8 | E5: infra: Lambda, DynamoDB, Cognito, hosting…
A6: + Opex / agente (viene de 'Resumen' — fuente única) | B6: =Resumen!B10 | C6: =Resumen!C10 | D6: =Resumen!D10 | E6: soporte, dev, ventas, overhead
A7: = Costo de servir / agente | B7: =B5+B6 | C7: =C5+C6 | D7: =D5+D6
A9: B) Tres formas de poner el precio
A10: Margen bruto objetivo (para costo-plus) | B10: 0.75 | C10: 0.75 | D10: 0.75 | E10: EDITABLE (0–1)
A11: 1) COSTO-PLUS · precio = costo de servir ÷ (1 − margen) | B11: =B7/(1-B10) | C11: =C7/(1-C10) | D11: =D7/(1-D10) | E11: piso: cubre costo + margen
A12: Techo de VALOR: licencia/agente de Kommo+Chattigo+Salesforce | B12: 120 | C12: 110 | D12: 95 | E12: EDITABLE — software que reemplaza
A13: % de ese valor que captura ARIA | B13: 0.35 | C13: 0.35 | D13: 0.3 | E13: EDITABLE (0–1)
A14: 2) POR VALOR · precio = techo de valor × % capturado | B14: =B12*B13 | C14: =C12*C13 | D14: =D12*D13 | E14: techo: lo que el cliente ya paga hoy
A15: Markup sobre el AWS del cliente (servicio gestionado) | B15: 0.15 | C15: 0.12 | D15: 0.1 | E15: EDITABLE (0–1)
A16: 3) POR SERVICIO · markup × (consumo BYO / agente) | B16: =Resumen!B5*B15 | C16: =Resumen!C5*C15 | D16: =Resumen!D5*D15 | E16: add-on: el CLIENTE sigue pagando su AWS; ARIA solo lo opera
A18: C) Recomendación ARIA — híbrido: suscripción por agente + consumo BYO a costo
A19: » Precio recomendado / agente (= tarifa de 'Resumen') | B19: =Resumen!B13 | C19: =Resumen!C13 | D19: =Resumen!D13 | E19: editá la tarifa en 'Resumen'
A20: Margen bruto resultante | B20: =(B19-B7)/B19 | C20: =(C19-C7)/C19 | D20: =(D19-D7)/D19
A21: Descuento vs. su software actual (techo de valor) | B21: =1-B19/B12 | C21: =1-C19/C12 | D21: =1-D19/D12 | E21: qué tan barato es el SOFTWARE vs. lo que paga hoy
A22: Ingreso ARIA / tenant (precio × agentes) | B22: =B19*Parametros!B4 | C22: =C19*Parametros!C4 | D22: =D19*Parametros!D4
A23: Utilidad bruta ARIA / tenant | B23: =(B19-B7)*Parametros!B4 | C23: =(C19-C7)*Parametros!C4 | D23: =(D19-D7)*Parametros!D4
A25: D) Si ARIA HOSPEDA la instancia del cliente (NO-BYO) — alerta de cobertura
A26: Costo total si corre en la cuenta de ARIA / agente | B26: =Resumen!B5+B7 | C26: =Resumen!C5+C7 | D26: =Resumen!D5+D7 | E26: instancia del cliente + servir: aquí la suscripción NO alcanza
A27: Precio all-inclusive para break-even / agente | B27: =Resumen!B5+B7 | C27: =Resumen!C5+C7 | D27: =Resumen!D5+D7 | E27: piso absoluto: 0% margen
A28: Precio all-inclusive para margen objetivo / agente | B28: =(Resumen!B5+B7)/(1-B10) | C28: =(Resumen!C5+C7)/(1-C10) | D28: =(Resumen!D5+D7)/(1-D10) | E28: con el margen objetivo de arriba
A30: Metodología — cómo se decide el precio:
A31: • Costo-plus (PISO): la infraestructura de ARIA cuesta ~US$3–5 por agente al mes. Aun sumando soporte y
A32: desarrollo, el costo de servir queda bajo. Cobrar 'a costo + margen' dejaría mucha plata sobre la mesa.
A33: • Por valor (TECHO): el cliente HOY paga US$80–200 por agente en LICENCIAS de Kommo, Chattigo y Salesforce.
A34: Ese es el techo. ARIA captura ~1/3 de ese valor y aun así es muchísimo más barato para él.
A35: • Por servicio (ADD-ON): en BYO el cliente paga su propio AWS. ARIA puede gestionarlo con un markup (10–15%)
A36: como servicio administrado — el cliente SIGUE pagando su AWS, ARIA solo lo opera. No es el modelo principal.
A38: Recomendación: SUSCRIPCIÓN POR AGENTE (precio plano, predecible) + el consumo variable de AWS (telefonía,
A39: WhatsApp, IA) que el cliente paga directo a AWS, a costo y sin markup. Es transparente, fácil de vender y
A40: deja 63–71% de margen bruto. El 'por servicio' se ofrece sólo como add-on gestionado.
A42: ⚠ ALERTA (sección D): si en un PILOTO o en 'AWS gestionado' la instancia corre en la CUENTA DE ARIA en vez de
A43: la del cliente, ARIA paga TAMBIÉN la instancia (~$96–124/agente). Ahí la suscripción de $29–45 NO cubre: hay
... A48: costo AWS (normalmente más barata que la que viene 'empaquetada' en las plataformas tradicionales).
